[2021-10-15 09:40:48,311] driver_util.py->__init__ line:30 [INFO] : 当前正在启动app,请稍后.....
[2021-10-15 09:40:49,322] remote_connection.py->__init__ line:117 [INFO] : Could not connect to port 4723 on host 127.0.0.1
[2021-10-15 09:40:49,323] remote_connection.py->__init__ line:136 [INFO] : Could not get IP address for host: 127.0.0.1
[2021-10-15 09:40:51,366] connectionpool.py->urlopen line:781 [WARNING] : Retrying (Retry(total=2, connect=None, read=None, redirect=None, status=None)) after connection broken by 'NewConnectionError('<urllib3.connection.HTTPConnection object at 0x03519050>: Failed to establish a new connection: [WinError 10061] 由于目标计算机积极拒绝，无法连接。')': /wd/hub/session
[2021-10-15 09:40:53,404] connectionpool.py->urlopen line:781 [WARNING] : Retrying (Retry(total=1, connect=None, read=None, redirect=None, status=None)) after connection broken by 'NewConnectionError('<urllib3.connection.HTTPConnection object at 0x035190B0>: Failed to establish a new connection: [WinError 10061] 由于目标计算机积极拒绝，无法连接。')': /wd/hub/session
[2021-10-15 09:40:55,436] connectionpool.py->urlopen line:781 [WARNING] : Retrying (Retry(total=0, connect=None, read=None, redirect=None, status=None)) after connection broken by 'NewConnectionError('<urllib3.connection.HTTPConnection object at 0x03519170>: Failed to establish a new connection: [WinError 10061] 由于目标计算机积极拒绝，无法连接。')': /wd/hub/session
[2021-10-15 09:41:07,576] driver_util.py->__init__ line:30 [INFO] : 当前正在启动app,请稍后.....
[2021-10-15 09:42:30,834] driver_util.py->__init__ line:30 [INFO] : 当前正在启动app,请稍后.....
[2021-10-15 09:43:19,685] driver_util.py->__init__ line:30 [INFO] : 当前正在启动app,请稍后.....
[2021-10-15 09:57:38,562] yaml_utils.py->read_yaml_key line:43 [INFO] : 读取yml文件中...
[2021-10-15 09:58:28,210] yaml_utils.py->read_yaml_key line:43 [INFO] : 读取yml文件中...
[2021-10-15 09:59:01,940] yaml_utils.py->read_yaml_key line:43 [INFO] : 读取yml文件中...
[2021-10-15 10:05:46,749] yaml_utils.py->read_yaml line:31 [ERROR] : 未找到文件，请检查对应路径,[while parsing a block mapping
  in "C:\Users\admin\PycharmProjects\Yaoweilai_UI\common\..\test_data\two.yaml", line 5, column 7
expected <block end>, but found '['
  in "C:\Users\admin\PycharmProjects\Yaoweilai_UI\common\..\test_data\two.yaml", line 5, column 24]
[2021-10-15 10:05:46,754] yaml_utils.py->read_yaml_key line:46 [ERROR] : 未找到文件，请检查对应路径,[while parsing a block mapping
  in "C:\Users\admin\PycharmProjects\Yaoweilai_UI\common\..\test_data\two.yaml", line 5, column 7
expected <block end>, but found '['
  in "C:\Users\admin\PycharmProjects\Yaoweilai_UI\common\..\test_data\two.yaml", line 5, column 24]
[2021-10-15 10:05:59,816] yaml_utils.py->read_yaml line:31 [ERROR] : 未找到文件，请检查对应路径,[while parsing a flow sequence
  in "C:\Users\admin\PycharmProjects\Yaoweilai_UI\common\..\test_data\two.yaml", line 5, column 15
expected ',' or ']', but got '['
  in "C:\Users\admin\PycharmProjects\Yaoweilai_UI\common\..\test_data\two.yaml", line 5, column 56]
[2021-10-15 10:05:59,820] yaml_utils.py->read_yaml_key line:46 [ERROR] : 未找到文件，请检查对应路径,[while parsing a flow sequence
  in "C:\Users\admin\PycharmProjects\Yaoweilai_UI\common\..\test_data\two.yaml", line 5, column 15
expected ',' or ']', but got '['
  in "C:\Users\admin\PycharmProjects\Yaoweilai_UI\common\..\test_data\two.yaml", line 5, column 56]
[2021-10-15 10:06:12,708] yaml_utils.py->read_yaml_key line:43 [INFO] : 读取yml文件中...
[2021-10-15 13:19:47,195] yaml_utils.py->read_yaml_key line:46 [ERROR] : 未找到文件，请检查对应路径,['app_consulting']
